<?xml version="1.0" encoding="UTF-8"?>
<robot name="KR3R400Z150_2">
  <!-- ===== 材质定义 ===== -->
  <material name="kuka_pedestal">
    <color rgba="0.6 0.6 0.6 1.0"/>
  </material>
  <material name="kuka_orange">
    <color rgba="1.0 0.5 0.0 1.0"/>
  </material>
  <link name="base_link">
    <inertial>
      <origin rpy="0.00000000 0.00000000 0.00000000" xyz="-0.01000000 0.00000000 0.07900000"/>
      <mass value="3.40600000"/>
      <inertia ixx="0.01100000" ixy="0.00000000" ixz="0.00000000" iyy="0.01200000" iyz="0.00000000" izz="0.00900000"/>
    </inertial>
    <visual>
      <geometry>
        <mesh filename="package://kuka_kr3_R400Z150_2/meshes/visual/base_link.stl" scale="1.0 1.0 1.0"/>
      </geometry>
      <origin rpy="0 0 0"/>
      <material name="kuka_pedestal"/>
    </visual>
    <collision>
      <geometry>
        <mesh filename="package://kuka_kr3_R400Z150_2/meshes/collision/base_link.stl" scale="1.0 1.0 1.0"/>
      </geometry>
      <origin rpy="0 0 0"/>
    </collision>
  </link>
  <link name="link1">
    <inertial>
      <origin rpy="0.00000000 0.00000000 0.00000000" xyz="0.09000000 0.00000000 0.02400000"/>
      <mass value="1.63500000"/>
      <inertia ixx="0.00100000" ixy="0.00000000" ixz="0.00000000" iyy="0.01500000" iyz="0.00000000" izz="0.01600000"/>
    </inertial>
    <visual>
      <geometry>
        <mesh filename="package://kuka_kr3_R400Z150_2/meshes/visual/link_1.stl" scale="1.0 1.0 1.0"/>
      </geometry>
      <origin rpy="0 0 0" xyz="0.0 0 0"/>
      <material name="kuka_orange"/>
    </visual>
    <collision>
      <geometry>
        <mesh filename="package://kuka_kr3_R400Z150_2/meshes/collision/link_1.stl" scale="1.0 1.0 1.0"/>
      </geometry>
      <origin rpy="0 0 0" xyz="0.0 0 0"/>
    </collision>
  </link>
  <link name="link2">
    <inertial>
      <origin rpy="0.00000000 0.00000000 0.00000000" xyz="0.06800000 0.00000000 0.08800000"/>
      <mass value="5.97700000"/>
      <inertia ixx="0.02300000" ixy="0.00000000" ixz="-0.00400000" iyy="0.04200000" iyz="0.00000000" izz="0.03100000"/>
    </inertial>
    <visual>
      <geometry>
        <mesh filename="package://kuka_kr3_R400Z150_2/meshes/visual/link_2.stl" scale="1.0 1.0 1.0"/>
      </geometry>
      <origin rpy="0 0 0" xyz="0 0 0"/>
      <material name="kuka_orange"/>
    </visual>
    <collision>
      <geometry>
        <mesh filename="package://kuka_kr3_R400Z150_2/meshes/collision/link_2.stl" scale="1.0 1.0 1.0"/>
      </geometry>
      <origin rpy="0 0 0" xyz="0.0 0 0"/>
    </collision>
  </link>
  <link name="link3">
    <inertial>
      <origin rpy="0.00000000 0.00000000 0.00000000" xyz="0.00000000 0.00000000 0.18300000"/>
      <mass value="0.33100000"/>
      <inertia ixx="0.00500000" ixy="0.00000000" ixz="0.00000000" iyy="0.00500000" iyz="0.00000000" izz="0.00000000"/>
    </inertial>
    <visual>
      <geometry>
        <mesh filename="package://kuka_kr3_R400Z150_2/meshes/visual/link_3.stl" scale="1.0 1.0 1.0"/>
      </geometry>
      <origin rpy="0 0 0" xyz="0 0 0"/>
      <material name="kuka_pedestal"/>
    </visual>
    <collision>
      <geometry>
        <mesh filename="package://kuka_kr3_R400Z150_2/meshes/collision/link_3.stl" scale="1.0 1.0 1.0"/>
      </geometry>
      <origin rpy="0 0 0" xyz="0 0 0"/>
    </collision>
  </link>
  <link name="link4">
    <inertial>
      <origin rpy="0.00000000 0.00000000 0.00000000" xyz="0.00000000 0.00000000 0.00000000"/>
      <mass value="0.00000000"/>
      <inertia ixx="0.00000000" ixy="0.00000000" ixz="0.00000000" iyy="0.00000000" iyz="0.00000000" izz="0.00000000"/>
    </inertial>
  </link>
  <!-- ===== 额外框架 ===== -->
  <link name="flange"/>
  <link name="base"/>
  <joint name="joint1" type="revolute">
    <parent link="base_link"/>
    <child link="link1"/>
    <origin rpy="0.00000000 0.00000000 0.00000000" xyz="0.00000000 0.00000000 0.1650"/>
    <axis xyz="0.00000000 0.00000000 1.00000000"/>
    <limit lower="-2.5307" upper="2.5307" effort="0" velocity="0"/>
  </joint>
  <joint name="joint2" type="revolute">
    <parent link="link1"/>
    <child link="link2"/>
    <origin rpy="0.00000000 0.00000000 0.00000000" xyz="0.22500000 0.00000000 0.04000000"/>
    <axis xyz="0.00000000 0.00000000 1.00000000"/>
    <limit lower="-2.5307" upper="2.5307" effort="0" velocity="0"/>
  </joint>
  <joint name="joint3" type="prismatic">
    <parent link="link2"/>
    <child link="link3"/>
    <origin rpy="0 0.00000000 0.00000000" xyz="0.17500000 0.00000000 -0.06400000"/>
    <axis xyz="0.00000000 0.00000000 1.00000000"/>
    <limit lower="-0.15" upper="0.000000" effort="0" velocity="0"/>
  </joint>
  <joint name="joint4" type="revolute">
    <parent link="link3"/>
    <child link="link4"/>
    <origin rpy="0.00000000 0.00000000 0.00000000" xyz="0.00000000 0.00000000 0.00000000"/>
    <axis xyz="0.00000000 0.00000000 1.00000000"/>
    <limit lower="-3.14159265" upper="3.14159265" effort="0" velocity="0"/>
  </joint>
  <!-- ===== 固定关节 ===== -->
  <joint name="joint4-flange" type="fixed">
    <parent link="link4"/>
    <child link="flange"/>
    <origin xyz="0 0 0" rpy="0 1.570796326794897 0"/>
  </joint>
  <joint name="base-base_link" type="fixed">
    <origin xyz="0 0 0" rpy="0 0 0"/>
    <parent link="base"/>
    <child link="base_link"/>
  </joint>
</robot>