<?xml version="1.0"?>
<robot name="kuka_kr6r900-2">
  <!-- ===== 材质定义 ===== -->
  <material name="kuka_pedestal">
    <color rgba="0.6 0.6 0.6 1.0"/>
  </material>
  <material name="kuka_orange">
    <color rgba="1.0 0.5 0.0 1.0"/>
  </material>
  <!-- ===== 连杆 1: base_link ===== -->
  <link name="base_link">
    <inertial>
      <origin rpy="0.00000000 0.00000000 0.00000000" xyz="-0.02000000 0.00000000 0.12000000"/>
      <mass value="15.57000000"/>
      <inertia ixx="0.11000000" ixy="0.00000000" ixz="0.00000000" iyy="0.13000000" iyz="0.00000000" izz="0.11000000"/>
    </inertial>
    <visual>
      <origin xyz="0 0 0" rpy="0 0 0"/>
      <geometry>
        <mesh filename="package://kuka_kr6_R900_2/meshes/visual/base_link.STL"/>
      </geometry>
      <material name="kuka_pedestal"/>
    </visual>
    <collision>
      <origin xyz="0 0 0" rpy="0 0 0"/>
      <geometry>
        <mesh filename="package://kuka_kr6_R900_2/meshes/visual/base_link.STL"/>
      </geometry>
    </collision>
  </link>
  <!-- ===== 连杆 2: link_1 ===== -->
  <link name="link_1">
    <inertial>
      <origin rpy="0.00000000 0.00000000 0.00000000" xyz="0.01000000 0.00000000 -0.07000000"/>
      <mass value="9.34000000"/>
      <inertia ixx="0.11000000" ixy="0.00000000" ixz="0.01000000" iyy="0.07000000" iyz="0.00000000" izz="0.08000000"/>
    </inertial>
    <visual>
      <origin xyz="0 0 0" rpy="0 0 0"/>
      <geometry>
        <mesh filename="package://kuka_kr6_R900_2/meshes/collision/link_1.STL"/>
      </geometry>
      <material name="kuka_orange"/>
    </visual>
    <collision>
      <origin xyz="0 0 0" rpy="0 0 0"/>
      <geometry>
        <mesh filename="package://kuka_kr6_R900_2/meshes/collision/link_1.STL"/>
      </geometry>
    </collision>
  </link>
  <!-- ===== 连杆 3: link_2 ===== -->
  <link name="link_2">
    <inertial>
      <origin rpy="0.00000000 0.00000000 0.00000000" xyz="0.21100000 0.00100000 0.00800000"/>
      <mass value="15.47200000"/>
      <inertia ixx="0.08400000" ixy="0.00400000" ixz="0.00200000" iyy="0.46500000" iyz="0.00000000" izz="0.50900000"/>
    </inertial>
    <visual>
      <origin xyz="0 0 0" rpy="0 0 0"/>
      <geometry>
        <mesh filename="package://kuka_kr6_R900_2/meshes/visual/link_2.STL"/>
      </geometry>
      <material name="kuka_orange"/>
    </visual>
    <collision>
      <origin xyz="0 0 0" rpy="0 0 0"/>
      <geometry>
        <mesh filename="package://kuka_kr6_R900_2/meshes/collision/link_2.STL"/>
      </geometry>
    </collision>
  </link>
  <!-- ===== 连杆 4: link_3 ===== -->
  <link name="link_3">
    <inertial>
      <origin rpy="0.00000000 0.00000000 0.00000000" xyz="0.05200000 -0.00300000 0.01100000"/>
      <mass value="6.36200000"/>
      <inertia ixx="0.01700000" ixy="0.00100000" ixz="0.00500000" iyy="0.04600000" iyz="0.00000000" izz="0.04400000"/>
    </inertial>
    <visual>
      <origin xyz="0 0 0" rpy="0 0 0"/>
      <geometry>
        <mesh filename="package://kuka_kr6_R900_2/meshes/visual/link_3.STL"/>
      </geometry>
      <material name="kuka_orange"/>
    </visual>
    <collision>
      <origin xyz="0 0 0" rpy="0 0 0"/>
      <geometry>
        <mesh filename="package://kuka_kr6_R900_2/meshes/collision/link_3.STL"/>
      </geometry>
    </collision>
  </link>
  <!-- ===== 连杆 5: link_4 ===== -->
  <link name="link_4">
    <inertial>
      <origin rpy="0.00000000 0.00000000 0.00000000" xyz="0.30900000 0.00200000 0.00000000"/>
      <mass value="3.92500000"/>
      <inertia ixx="0.01100000" ixy="0.00100000" ixz="0.00000000" iyy="0.01700000" iyz="0.00000000" izz="0.02200000"/>
    </inertial>
    <visual>
      <origin xyz="0 0 0" rpy="0 0 0"/>
      <geometry>
        <mesh filename="package://kuka_kr6_R900_2/meshes/visual/link_4.STL"/>
      </geometry>
      <material name="kuka_orange"/>
    </visual>
    <collision>
      <origin xyz="0 0 0" rpy="0 0 0"/>
      <geometry>
        <mesh filename="package://kuka_kr6_R900_2/meshes/collision/link_4.STL"/>
      </geometry>
    </collision>
  </link>
  <!-- ===== 连杆 6: link_5 ===== -->
  <link name="link_5">
    <inertial>
      <origin rpy="0.00000000 0.00000000 0.00000000" xyz="0.01100000 -0.00100000 0.00000000"/>
      <mass value="1.22200000"/>
      <inertia ixx="0.00100000" ixy="0.00000000" ixz="0.00000000" iyy="0.00200000" iyz="0.00000000" izz="0.00200000"/>
    </inertial>
    <visual>
      <origin xyz="0 0 0" rpy="0 0 0"/>
      <geometry>
        <mesh filename="package://kuka_kr6_R900_2/meshes/visual/link_5.STL"/>
      </geometry>
      <material name="kuka_orange"/>
    </visual>
    <collision>
      <origin xyz="0 0 0" rpy="0 0 0"/>
      <geometry>
        <mesh filename="package://kuka_kr6_R900_2/meshes/collision/link_5.STL"/>
      </geometry>
    </collision>
  </link>
  <!-- ===== 连杆 7: link_6 ===== -->
  <link name="link_6">
    <inertial>
      <origin rpy="0.00000000 0.00000000 0.00000000" xyz="-0.01300000 0.00000000 0.00000000"/>
      <mass value="0.58500000"/>
      <inertia ixx="0.00000000" ixy="0.00000000" ixz="0.00000000" iyy="0.00000000" iyz="0.00000000" izz="0.00000000"/>
    </inertial>
    <visual>
      <origin xyz="0 0 0" rpy="0 0 0"/>
      <geometry>
        <mesh filename="package://kuka_kr6_R900_2/meshes/visual/link_6.STL"/>
      </geometry>
      <material name="kuka_pedestal"/>
    </visual>
    <collision>
      <origin xyz="0 0 0" rpy="0 0 0"/>
      <geometry>
        <mesh filename="package://kuka_kr6_R900_2/meshes/collision/link_6.STL"/>
      </geometry>
    </collision>
  </link>
  <!-- ===== 额外框架 ===== -->
  <link name="flange"/>
  <link name="base"/>
  <!-- ===== 关节定义 ===== -->
  <joint name="joint_a1" type="revolute">
    <origin xyz="0 0 0.4" rpy="0 0 0"/>
    <parent link="base_link"/>
    <child link="link_1"/>
    <axis xyz="0 0 -1"/>
    <limit effort="0" lower="-2.967" upper="2.967" velocity="6.283"/>
  </joint>
  <joint name="joint_a2" type="revolute">
    <origin xyz="0.025 0 0.0" rpy="0 0 0"/>
    <parent link="link_1"/>
    <child link="link_2"/>
    <axis xyz="0 1 0"/>
    <limit effort="0" lower="-3.316" upper="0.785" velocity="5.236"/>
  </joint>
  <joint name="joint_a3" type="revolute">
    <origin xyz="0.455 0 0" rpy="0 0 0"/>
    <parent link="link_2"/>
    <child link="link_3"/>
    <axis xyz="0 1 0"/>
    <limit effort="0" lower="-2.094" upper="2.723" velocity="6.283"/>
  </joint>
  <joint name="joint_a4" type="revolute">
    <origin xyz="0.0 0 0.025" rpy="0 0 0"/>
    <parent link="link_3"/>
    <child link="link_4"/>
    <axis xyz="-1 0 0"/>
    <limit effort="0" lower="-3.229" upper="3.229" velocity="6.649"/>
  </joint>
  <joint name="joint_a5" type="revolute">
    <origin xyz="0.42 0 0" rpy="0 0 0"/>
    <parent link="link_4"/>
    <child link="link_5"/>
    <axis xyz="0 1 0"/>
    <limit effort="0" lower="-2.094" upper="2.094" velocity="6.772"/>
  </joint>
  <joint name="joint_a6" type="revolute">
    <origin xyz="0.09 0 0" rpy="0 0 0"/>
    <parent link="link_5"/>
    <child link="link_6"/>
    <axis xyz="-1 0 0"/>
    <limit effort="0" lower="-6.108" upper="6.108" velocity="10.734"/>
  </joint>
  <!-- ===== 固定关节 ===== -->
  <joint name="joint_a6-flange" type="fixed">
    <parent link="link_6"/>
    <child link="flange"/>
    <origin xyz="0 0 0" rpy="0 1.570796326794897 0"/>
  </joint>
  <joint name="base-base_link" type="fixed">
    <origin xyz="0 0 0" rpy="0 0 0"/>
    <parent link="base"/>
    <child link="base_link"/>
  </joint>
</robot>